03/06/2023 13:30:55 [ INFO ] __main__ : Started Pygramme
03/06/2023 13:30:55 [ DEBUG ] __main__ : C:\Users\legai\Documents\__Perso\ProductionPerso\pygramme
03/06/2023 13:30:55 [ ERROR ] __main__ : An unhandled exception occured
Traceback (most recent call last):
  File "C:\Users\legai\Documents\__Perso\ProductionPerso\pygramme\src\main.py", line 57, in <module>
    main()
  File "C:\Users\legai\Documents\__Perso\ProductionPerso\pygramme\src\main.py", line 50, in main
    raise ValueError('test')
ValueError: test

03/06/2023 13:30:55 [ INFO ] __main__ : Exiting Pygramme
